<?xml version="1.0" encoding="utf-8"?>
<!-- This URDF was automatically created by SolidWorks to URDF Exporter! Originally created by Stephen Brawner (brawner@gmail.com) 
     Commit Version: 1.6.0-4-g7f85cfe  Build Version: 1.6.7995.38578
     For more information, please see http://wiki.ros.org/sw_urdf_exporter -->
<robot
  name="m1pro_description">
  <link name="dummy_link" />
  <joint
    name="dummy_joint"
    type="fixed">
    <parent
      link="dummy_link" />
    <child
      link="base_link" />
  </joint>
  <link
    name="base_link">
    <inertial>
      <origin
        xyz="0.0020887 0.24592 -9.2948E-06"
        rpy="0 0 0" />
      <mass
        value="1.6489" />
      <inertia
        ixx="0.090971"
        ixy="0.002094"
        ixz="-4.8449E-06"
        iyy="0.009863"
        iyz="1.4427E-05"
        izz="0.089585" />
    </inertial>
    <visual>
      <origin
        xyz="0 0 0"
        rpy="0 0 0" />
      <geometry>
        <mesh
          filename="package://m1pro_description/meshes/base_link.STL" />
      </geometry>
      <material
        name="">
        <color
          rgba="0.79216 0.81961 0.93333 1" />
      </material>
    </visual>
    <collision>
      <origin
        xyz="0 0 0"
        rpy="0 0 0" />
      <geometry>
        <mesh
          filename="package://m1pro_description/meshes/base_link.STL" />
      </geometry>
    </collision>
  </link>
  <link
    name="Link1">
    <inertial>
      <origin
        xyz="0.096709 6.1822E-05 0.090051"
        rpy="0 0 0" />
      <mass
        value="0.34234" />
      <inertia
        ixx="0.0016183"
        ixy="1.9963E-06"
        ixz="-0.00029873"
        iyy="0.0016941"
        iyz="8.0481E-07"
        izz="0.00088121" />
    </inertial>
    <visual>
      <origin
        xyz="0 0 0"
        rpy="0 0 0" />
      <geometry>
        <mesh
          filename="package://m1pro_description/meshes/Link1.STL" />
      </geometry>
      <material
        name="">
        <color
          rgba="0.79216 0.81961 0.93333 1" />
      </material>
    </visual>
    <collision>
      <origin
        xyz="0 0 0"
        rpy="0 0 0" />
      <geometry>
        <mesh
          filename="package://m1pro_description/meshes/Link1.STL" />
      </geometry>
    </collision>
  </link>
  <joint
    name="joint1"
    type="prismatic">
    <origin
      xyz="-0.003 0 0.0959"
      rpy="0 0 0" />
    <parent
      link="base_link" />
    <child
      link="Link1" />
    <axis
      xyz="0 0 1" />
    <limit
      lower="0"
      upper="0.25"
      effort="0"
      velocity="0" />
  </joint>
  <link
    name="Link2">
    <inertial>
      <origin
        xyz="0.11428 -2.1681E-05 0.038255"
        rpy="0 0 0" />
      <mass
        value="0.37995" />
      <inertia
        ixx="0.00096644"
        ixy="2.2955E-06"
        ixz="-0.00059955"
        iyy="0.0031741"
        iyz="-2.4057E-09"
        izz="0.0027963" />
    </inertial>
    <visual>
      <origin
        xyz="0 0 0"
        rpy="0 0 0" />
      <geometry>
        <mesh
          filename="package://m1pro_description/meshes/Link2.STL" />
      </geometry>
      <material
        name="">
        <color
          rgba="0.79216 0.81961 0.93333 1" />
      </material>
    </visual>
    <collision>
      <origin
        xyz="0 0 0"
        rpy="0 0 0" />
      <geometry>
        <mesh
          filename="package://m1pro_description/meshes/Link2.STL" />
      </geometry>
    </collision>
  </link>
  <joint
    name="joint2"
    type="continuous">
    <origin
      xyz="0.123 0 0.0099745"
      rpy="0 0 0" />
    <parent
      link="Link1" />
    <child
      link="Link2" />
    <axis
      xyz="0 0 1" />
  </joint>
  <link
    name="Link3">
    <inertial>
      <origin
        xyz="0.097934 0.00036211 0.0056251"
        rpy="0 0 0" />
      <mass
        value="0.33738" />
      <inertia
        ixx="0.00099637"
        ixy="-1.0881E-06"
        ixz="-0.00074781"
        iyy="0.003254"
        iyz="-3.8055E-07"
        izz="0.0025681" />
    </inertial>
    <visual>
      <origin
        xyz="0 0 0"
        rpy="0 0 0" />
      <geometry>
        <mesh
          filename="package://m1pro_description/meshes/Link3.STL" />
      </geometry>
      <material
        name="">
        <color
          rgba="0.79216 0.81961 0.93333 1" />
      </material>
    </visual>
    <collision>
      <origin
        xyz="0 0 0"
        rpy="0 0 0" />
      <geometry>
        <mesh
          filename="package://m1pro_description/meshes/Link3.STL" />
      </geometry>
    </collision>
  </link>
  <joint
    name="joint3"
    type="continuous">
    <origin
      xyz="0.2 0 0"
      rpy="-0.017453 0 0.034228" />
    <parent
      link="Link2" />
    <child
      link="Link3" />
    <axis
      xyz="0 0.017452 -0.99985" />
  </joint>
  <link
    name="Link4">
    <inertial>
      <origin
        xyz="3.505E-13 -1.5772E-11 0.06"
        rpy="0 0 0" />
      <mass
        value="0.010941" />
      <inertia
        ixx="7.2568E-06"
        ixy="4.4734E-21"
        ixz="6.1388E-17"
        iyy="7.2589E-06"
        iyz="-4.5944E-15"
        izz="4.4133E-07" />
    </inertial>
    <visual>
      <origin
        xyz="0 0 0.06"
        rpy="0 0 0" />
      <geometry>
        <mesh
          filename="package://m1pro_description/meshes/Link4.STL" />
      </geometry>
      <material
        name="">
        <color
          rgba="0.79216 0.81961 0.93333 1" />
      </material>
    </visual>
    <collision>
      <origin
        xyz="0 0 0.06"
        rpy="0 0 0" />
      <geometry>
        <mesh
          filename="package://m1pro_description/meshes/Link4.STL" />
      </geometry>
    </collision>
  </link>
  <joint
    name="joint4"
    type="continuous">
    <origin
      xyz="0.2 0.00020895 -0.08081"
      rpy="0 0 0" />
    <parent
      link="Link3" />
    <child
      link="Link4" />
    <axis
      xyz="0 0 1" />
  </joint>
</robot>
